ERROR:root:'totalDescuentoLegalesCompleto'
DEBUG:django.template:Exception while resolving variable 'cosalarioBaseMensual' in template 'fideicomiso_form.html'.
Traceback (most recent call last):
  File "/Users/andresrdrgz_/Documents/PACIFICO/venv/lib/python3.11/site-packages/django/template/base.py", line 883, in _resolve_lookup
    current = current[bit]
              ~~~~~~~^^^^^
KeyError: 'cosalarioBaseMensual'

During handling of the above exception, another exception occurred:

Traceback (most recent call last):
  File "/Users/andresrdrgz_/Documents/PACIFICO/venv/lib/python3.11/site-packages/django/template/base.py", line 893, in _resolve_lookup
    current = getattr(current, bit)
              ^^^^^^^^^^^^^^^^^^^^^
AttributeError: 'dict' object has no attribute 'cosalarioBaseMensual'

During handling of the above exception, another exception occurred:

Traceback (most recent call last):
  File "/Users/andresrdrgz_/Documents/PACIFICO/venv/lib/python3.11/site-packages/django/template/base.py", line 899, in _resolve_lookup
    current = current[int(bit)]
                      ^^^^^^^^
ValueError: invalid literal for int() with base 10: 'cosalarioBaseMensual'

During handling of the above exception, another exception occurred:

Traceback (most recent call last):
  File "/Users/andresrdrgz_/Documents/PACIFICO/venv/lib/python3.11/site-packages/django/template/base.py", line 906, in _resolve_lookup
    raise VariableDoesNotExist(
django.template.base.VariableDoesNotExist: Failed lookup for key [cosalarioBaseMensual] in {'auxMonto2': Decimal('14542.91'), 'r1': Decimal('14.00'), 'tasaEstimada': Decimal('9.10'), 'calcComiCierreFinal': Decimal('15.06'), 'auxPlazoPago': 72, 'wrkLetraSinSeguros': Decimal('271.29'), 'wrkLetraSeguro': Decimal('11.45'), 'wrkMontoLetra': Decimal('282.74'), 'montoMensualSeguro': Decimal('0.00'), 'wrkLetraConSeguros': Decimal('282.74'), 'tablaTotalPagos': Decimal('20357.28'), 'nombreCliente': 'asd', 'valorAuto': Decimal('12351.00'), 'abono': Decimal('0.00'), 'salarioBaseMensual': Decimal('1500.00'), 'totalDescuentosLegales': Decimal('263.08'), 'totalDescuentoDirecto': Decimal('350.00'), 'totalPagoVoluntario': Decimal('120.00'), 'salarioNetoActual': Decimal('766.92'), 'salarioNeto': Decimal('484.18'), 'porSalarioNeto': Decimal('32.28'), 'totalIngresosAdicionales': Decimal('0.00'), 'totalIngresosMensualesCompleto': Decimal('1500.00'), 'totalDescuentosLegalesCompleto': Decimal('263.08'), 'salarioNetoActualCompleto': Decimal('766.92'), 'salarioNetoCompleto': Decimal('484.18'), 'porSalarioNetoCompleto': Decimal('32.28'), 'numero_cotizacion': 19}
DEBUG:django.template:Exception while resolving variable 'cototalDescuentosLegales' in template 'fideicomiso_form.html'.
Traceback (most recent call last):
  File "/Users/andresrdrgz_/Documents/PACIFICO/venv/lib/python3.11/site-packages/django/template/base.py", line 883, in _resolve_lookup
    current = current[bit]
              ~~~~~~~^^^^^
KeyError: 'cototalDescuentosLegales'

During handling of the above exception, another exception occurred:

Traceback (most recent call last):
  File "/Users/andresrdrgz_/Documents/PACIFICO/venv/lib/python3.11/site-packages/django/template/base.py", line 893, in _resolve_lookup
    current = getattr(current, bit)
              ^^^^^^^^^^^^^^^^^^^^^
AttributeError: 'dict' object has no attribute 'cototalDescuentosLegales'

During handling of the above exception, another exception occurred:

Traceback (most recent call last):
  File "/Users/andresrdrgz_/Documents/PACIFICO/venv/lib/python3.11/site-packages/django/template/base.py", line 899, in _resolve_lookup
    current = current[int(bit)]
                      ^^^^^^^^
ValueError: invalid literal for int() with base 10: 'cototalDescuentosLegales'

During handling of the above exception, another exception occurred:

Traceback (most recent call last):
  File "/Users/andresrdrgz_/Documents/PACIFICO/venv/lib/python3.11/site-packages/django/template/base.py", line 906, in _resolve_lookup
    raise VariableDoesNotExist(
django.template.base.VariableDoesNotExist: Failed lookup for key [cototalDescuentosLegales] in {'auxMonto2': Decimal('14542.91'), 'r1': Decimal('14.00'), 'tasaEstimada': Decimal('9.10'), 'calcComiCierreFinal': Decimal('15.06'), 'auxPlazoPago': 72, 'wrkLetraSinSeguros': Decimal('271.29'), 'wrkLetraSeguro': Decimal('11.45'), 'wrkMontoLetra': Decimal('282.74'), 'montoMensualSeguro': Decimal('0.00'), 'wrkLetraConSeguros': Decimal('282.74'), 'tablaTotalPagos': Decimal('20357.28'), 'nombreCliente': 'asd', 'valorAuto': Decimal('12351.00'), 'abono': Decimal('0.00'), 'salarioBaseMensual': Decimal('1500.00'), 'totalDescuentosLegales': Decimal('263.08'), 'totalDescuentoDirecto': Decimal('350.00'), 'totalPagoVoluntario': Decimal('120.00'), 'salarioNetoActual': Decimal('766.92'), 'salarioNeto': Decimal('484.18'), 'porSalarioNeto': Decimal('32.28'), 'totalIngresosAdicionales': Decimal('0.00'), 'totalIngresosMensualesCompleto': Decimal('1500.00'), 'totalDescuentosLegalesCompleto': Decimal('263.08'), 'salarioNetoActualCompleto': Decimal('766.92'), 'salarioNetoCompleto': Decimal('484.18'), 'porSalarioNetoCompleto': Decimal('32.28'), 'numero_cotizacion': 19}
DEBUG:django.template:Exception while resolving variable 'cototalDescuentoDirecto' in template 'fideicomiso_form.html'.
Traceback (most recent call last):
  File "/Users/andresrdrgz_/Documents/PACIFICO/venv/lib/python3.11/site-packages/django/template/base.py", line 883, in _resolve_lookup
    current = current[bit]
              ~~~~~~~^^^^^
KeyError: 'cototalDescuentoDirecto'

During handling of the above exception, another exception occurred:

Traceback (most recent call last):
  File "/Users/andresrdrgz_/Documents/PACIFICO/venv/lib/python3.11/site-packages/django/template/base.py", line 893, in _resolve_lookup
    current = getattr(current, bit)
              ^^^^^^^^^^^^^^^^^^^^^
AttributeError: 'dict' object has no attribute 'cototalDescuentoDirecto'

During handling of the above exception, another exception occurred:

Traceback (most recent call last):
  File "/Users/andresrdrgz_/Documents/PACIFICO/venv/lib/python3.11/site-packages/django/template/base.py", line 899, in _resolve_lookup
    current = current[int(bit)]
                      ^^^^^^^^
ValueError: invalid literal for int() with base 10: 'cototalDescuentoDirecto'

During handling of the above exception, another exception occurred:

Traceback (most recent call last):
  File "/Users/andresrdrgz_/Documents/PACIFICO/venv/lib/python3.11/site-packages/django/template/base.py", line 906, in _resolve_lookup
    raise VariableDoesNotExist(
django.template.base.VariableDoesNotExist: Failed lookup for key [cototalDescuentoDirecto] in {'auxMonto2': Decimal('14542.91'), 'r1': Decimal('14.00'), 'tasaEstimada': Decimal('9.10'), 'calcComiCierreFinal': Decimal('15.06'), 'auxPlazoPago': 72, 'wrkLetraSinSeguros': Decimal('271.29'), 'wrkLetraSeguro': Decimal('11.45'), 'wrkMontoLetra': Decimal('282.74'), 'montoMensualSeguro': Decimal('0.00'), 'wrkLetraConSeguros': Decimal('282.74'), 'tablaTotalPagos': Decimal('20357.28'), 'nombreCliente': 'asd', 'valorAuto': Decimal('12351.00'), 'abono': Decimal('0.00'), 'salarioBaseMensual': Decimal('1500.00'), 'totalDescuentosLegales': Decimal('263.08'), 'totalDescuentoDirecto': Decimal('350.00'), 'totalPagoVoluntario': Decimal('120.00'), 'salarioNetoActual': Decimal('766.92'), 'salarioNeto': Decimal('484.18'), 'porSalarioNeto': Decimal('32.28'), 'totalIngresosAdicionales': Decimal('0.00'), 'totalIngresosMensualesCompleto': Decimal('1500.00'), 'totalDescuentosLegalesCompleto': Decimal('263.08'), 'salarioNetoActualCompleto': Decimal('766.92'), 'salarioNetoCompleto': Decimal('484.18'), 'porSalarioNetoCompleto': Decimal('32.28'), 'numero_cotizacion': 19}
DEBUG:django.template:Exception while resolving variable 'cototalPagoVoluntario' in template 'fideicomiso_form.html'.
Traceback (most recent call last):
  File "/Users/andresrdrgz_/Documents/PACIFICO/venv/lib/python3.11/site-packages/django/template/base.py", line 883, in _resolve_lookup
    current = current[bit]
              ~~~~~~~^^^^^
KeyError: 'cototalPagoVoluntario'

During handling of the above exception, another exception occurred:

Traceback (most recent call last):
  File "/Users/andresrdrgz_/Documents/PACIFICO/venv/lib/python3.11/site-packages/django/template/base.py", line 893, in _resolve_lookup
    current = getattr(current, bit)
              ^^^^^^^^^^^^^^^^^^^^^
AttributeError: 'dict' object has no attribute 'cototalPagoVoluntario'

During handling of the above exception, another exception occurred:

Traceback (most recent call last):
  File "/Users/andresrdrgz_/Documents/PACIFICO/venv/lib/python3.11/site-packages/django/template/base.py", line 899, in _resolve_lookup
    current = current[int(bit)]
                      ^^^^^^^^
ValueError: invalid literal for int() with base 10: 'cototalPagoVoluntario'

During handling of the above exception, another exception occurred:

Traceback (most recent call last):
  File "/Users/andresrdrgz_/Documents/PACIFICO/venv/lib/python3.11/site-packages/django/template/base.py", line 906, in _resolve_lookup
    raise VariableDoesNotExist(
django.template.base.VariableDoesNotExist: Failed lookup for key [cototalPagoVoluntario] in {'auxMonto2': Decimal('14542.91'), 'r1': Decimal('14.00'), 'tasaEstimada': Decimal('9.10'), 'calcComiCierreFinal': Decimal('15.06'), 'auxPlazoPago': 72, 'wrkLetraSinSeguros': Decimal('271.29'), 'wrkLetraSeguro': Decimal('11.45'), 'wrkMontoLetra': Decimal('282.74'), 'montoMensualSeguro': Decimal('0.00'), 'wrkLetraConSeguros': Decimal('282.74'), 'tablaTotalPagos': Decimal('20357.28'), 'nombreCliente': 'asd', 'valorAuto': Decimal('12351.00'), 'abono': Decimal('0.00'), 'salarioBaseMensual': Decimal('1500.00'), 'totalDescuentosLegales': Decimal('263.08'), 'totalDescuentoDirecto': Decimal('350.00'), 'totalPagoVoluntario': Decimal('120.00'), 'salarioNetoActual': Decimal('766.92'), 'salarioNeto': Decimal('484.18'), 'porSalarioNeto': Decimal('32.28'), 'totalIngresosAdicionales': Decimal('0.00'), 'totalIngresosMensualesCompleto': Decimal('1500.00'), 'totalDescuentosLegalesCompleto': Decimal('263.08'), 'salarioNetoActualCompleto': Decimal('766.92'), 'salarioNetoCompleto': Decimal('484.18'), 'porSalarioNetoCompleto': Decimal('32.28'), 'numero_cotizacion': 19}
DEBUG:django.template:Exception while resolving variable 'cosalarioNetoActual' in template 'fideicomiso_form.html'.
Traceback (most recent call last):
  File "/Users/andresrdrgz_/Documents/PACIFICO/venv/lib/python3.11/site-packages/django/template/base.py", line 883, in _resolve_lookup
    current = current[bit]
              ~~~~~~~^^^^^
KeyError: 'cosalarioNetoActual'

During handling of the above exception, another exception occurred:

Traceback (most recent call last):
  File "/Users/andresrdrgz_/Documents/PACIFICO/venv/lib/python3.11/site-packages/django/template/base.py", line 893, in _resolve_lookup
    current = getattr(current, bit)
              ^^^^^^^^^^^^^^^^^^^^^
AttributeError: 'dict' object has no attribute 'cosalarioNetoActual'

During handling of the above exception, another exception occurred:

Traceback (most recent call last):
  File "/Users/andresrdrgz_/Documents/PACIFICO/venv/lib/python3.11/site-packages/django/template/base.py", line 899, in _resolve_lookup
    current = current[int(bit)]
                      ^^^^^^^^
ValueError: invalid literal for int() with base 10: 'cosalarioNetoActual'

During handling of the above exception, another exception occurred:

Traceback (most recent call last):
  File "/Users/andresrdrgz_/Documents/PACIFICO/venv/lib/python3.11/site-packages/django/template/base.py", line 906, in _resolve_lookup
    raise VariableDoesNotExist(
django.template.base.VariableDoesNotExist: Failed lookup for key [cosalarioNetoActual] in {'auxMonto2': Decimal('14542.91'), 'r1': Decimal('14.00'), 'tasaEstimada': Decimal('9.10'), 'calcComiCierreFinal': Decimal('15.06'), 'auxPlazoPago': 72, 'wrkLetraSinSeguros': Decimal('271.29'), 'wrkLetraSeguro': Decimal('11.45'), 'wrkMontoLetra': Decimal('282.74'), 'montoMensualSeguro': Decimal('0.00'), 'wrkLetraConSeguros': Decimal('282.74'), 'tablaTotalPagos': Decimal('20357.28'), 'nombreCliente': 'asd', 'valorAuto': Decimal('12351.00'), 'abono': Decimal('0.00'), 'salarioBaseMensual': Decimal('1500.00'), 'totalDescuentosLegales': Decimal('263.08'), 'totalDescuentoDirecto': Decimal('350.00'), 'totalPagoVoluntario': Decimal('120.00'), 'salarioNetoActual': Decimal('766.92'), 'salarioNeto': Decimal('484.18'), 'porSalarioNeto': Decimal('32.28'), 'totalIngresosAdicionales': Decimal('0.00'), 'totalIngresosMensualesCompleto': Decimal('1500.00'), 'totalDescuentosLegalesCompleto': Decimal('263.08'), 'salarioNetoActualCompleto': Decimal('766.92'), 'salarioNetoCompleto': Decimal('484.18'), 'porSalarioNetoCompleto': Decimal('32.28'), 'numero_cotizacion': 19}
DEBUG:django.template:Exception while resolving variable 'cowrkLetraConSeguros' in template 'fideicomiso_form.html'.
Traceback (most recent call last):
  File "/Users/andresrdrgz_/Documents/PACIFICO/venv/lib/python3.11/site-packages/django/template/base.py", line 883, in _resolve_lookup
    current = current[bit]
              ~~~~~~~^^^^^
KeyError: 'cowrkLetraConSeguros'

During handling of the above exception, another exception occurred:

Traceback (most recent call last):
  File "/Users/andresrdrgz_/Documents/PACIFICO/venv/lib/python3.11/site-packages/django/template/base.py", line 893, in _resolve_lookup
    current = getattr(current, bit)
              ^^^^^^^^^^^^^^^^^^^^^
AttributeError: 'dict' object has no attribute 'cowrkLetraConSeguros'

During handling of the above exception, another exception occurred:

Traceback (most recent call last):
  File "/Users/andresrdrgz_/Documents/PACIFICO/venv/lib/python3.11/site-packages/django/template/base.py", line 899, in _resolve_lookup
    current = current[int(bit)]
                      ^^^^^^^^
ValueError: invalid literal for int() with base 10: 'cowrkLetraConSeguros'

During handling of the above exception, another exception occurred:

Traceback (most recent call last):
  File "/Users/andresrdrgz_/Documents/PACIFICO/venv/lib/python3.11/site-packages/django/template/base.py", line 906, in _resolve_lookup
    raise VariableDoesNotExist(
django.template.base.VariableDoesNotExist: Failed lookup for key [cowrkLetraConSeguros] in {'auxMonto2': Decimal('14542.91'), 'r1': Decimal('14.00'), 'tasaEstimada': Decimal('9.10'), 'calcComiCierreFinal': Decimal('15.06'), 'auxPlazoPago': 72, 'wrkLetraSinSeguros': Decimal('271.29'), 'wrkLetraSeguro': Decimal('11.45'), 'wrkMontoLetra': Decimal('282.74'), 'montoMensualSeguro': Decimal('0.00'), 'wrkLetraConSeguros': Decimal('282.74'), 'tablaTotalPagos': Decimal('20357.28'), 'nombreCliente': 'asd', 'valorAuto': Decimal('12351.00'), 'abono': Decimal('0.00'), 'salarioBaseMensual': Decimal('1500.00'), 'totalDescuentosLegales': Decimal('263.08'), 'totalDescuentoDirecto': Decimal('350.00'), 'totalPagoVoluntario': Decimal('120.00'), 'salarioNetoActual': Decimal('766.92'), 'salarioNeto': Decimal('484.18'), 'porSalarioNeto': Decimal('32.28'), 'totalIngresosAdicionales': Decimal('0.00'), 'totalIngresosMensualesCompleto': Decimal('1500.00'), 'totalDescuentosLegalesCompleto': Decimal('263.08'), 'salarioNetoActualCompleto': Decimal('766.92'), 'salarioNetoCompleto': Decimal('484.18'), 'porSalarioNetoCompleto': Decimal('32.28'), 'numero_cotizacion': 19}
DEBUG:django.template:Exception while resolving variable 'cosalarioNeto' in template 'fideicomiso_form.html'.
Traceback (most recent call last):
  File "/Users/andresrdrgz_/Documents/PACIFICO/venv/lib/python3.11/site-packages/django/template/base.py", line 883, in _resolve_lookup
    current = current[bit]
              ~~~~~~~^^^^^
KeyError: 'cosalarioNeto'

During handling of the above exception, another exception occurred:

Traceback (most recent call last):
  File "/Users/andresrdrgz_/Documents/PACIFICO/venv/lib/python3.11/site-packages/django/template/base.py", line 893, in _resolve_lookup
    current = getattr(current, bit)
              ^^^^^^^^^^^^^^^^^^^^^
AttributeError: 'dict' object has no attribute 'cosalarioNeto'

During handling of the above exception, another exception occurred:

Traceback (most recent call last):
  File "/Users/andresrdrgz_/Documents/PACIFICO/venv/lib/python3.11/site-packages/django/template/base.py", line 899, in _resolve_lookup
    current = current[int(bit)]
                      ^^^^^^^^
ValueError: invalid literal for int() with base 10: 'cosalarioNeto'

During handling of the above exception, another exception occurred:

Traceback (most recent call last):
  File "/Users/andresrdrgz_/Documents/PACIFICO/venv/lib/python3.11/site-packages/django/template/base.py", line 906, in _resolve_lookup
    raise VariableDoesNotExist(
django.template.base.VariableDoesNotExist: Failed lookup for key [cosalarioNeto] in {'auxMonto2': Decimal('14542.91'), 'r1': Decimal('14.00'), 'tasaEstimada': Decimal('9.10'), 'calcComiCierreFinal': Decimal('15.06'), 'auxPlazoPago': 72, 'wrkLetraSinSeguros': Decimal('271.29'), 'wrkLetraSeguro': Decimal('11.45'), 'wrkMontoLetra': Decimal('282.74'), 'montoMensualSeguro': Decimal('0.00'), 'wrkLetraConSeguros': Decimal('282.74'), 'tablaTotalPagos': Decimal('20357.28'), 'nombreCliente': 'asd', 'valorAuto': Decimal('12351.00'), 'abono': Decimal('0.00'), 'salarioBaseMensual': Decimal('1500.00'), 'totalDescuentosLegales': Decimal('263.08'), 'totalDescuentoDirecto': Decimal('350.00'), 'totalPagoVoluntario': Decimal('120.00'), 'salarioNetoActual': Decimal('766.92'), 'salarioNeto': Decimal('484.18'), 'porSalarioNeto': Decimal('32.28'), 'totalIngresosAdicionales': Decimal('0.00'), 'totalIngresosMensualesCompleto': Decimal('1500.00'), 'totalDescuentosLegalesCompleto': Decimal('263.08'), 'salarioNetoActualCompleto': Decimal('766.92'), 'salarioNetoCompleto': Decimal('484.18'), 'porSalarioNetoCompleto': Decimal('32.28'), 'numero_cotizacion': 19}
DEBUG:django.template:Exception while resolving variable 'coporSalarioNeto' in template 'fideicomiso_form.html'.
Traceback (most recent call last):
  File "/Users/andresrdrgz_/Documents/PACIFICO/venv/lib/python3.11/site-packages/django/template/base.py", line 883, in _resolve_lookup
    current = current[bit]
              ~~~~~~~^^^^^
KeyError: 'coporSalarioNeto'

During handling of the above exception, another exception occurred:

Traceback (most recent call last):
  File "/Users/andresrdrgz_/Documents/PACIFICO/venv/lib/python3.11/site-packages/django/template/base.py", line 893, in _resolve_lookup
    current = getattr(current, bit)
              ^^^^^^^^^^^^^^^^^^^^^
AttributeError: 'dict' object has no attribute 'coporSalarioNeto'

During handling of the above exception, another exception occurred:

Traceback (most recent call last):
  File "/Users/andresrdrgz_/Documents/PACIFICO/venv/lib/python3.11/site-packages/django/template/base.py", line 899, in _resolve_lookup
    current = current[int(bit)]
                      ^^^^^^^^
ValueError: invalid literal for int() with base 10: 'coporSalarioNeto'

During handling of the above exception, another exception occurred:

Traceback (most recent call last):
  File "/Users/andresrdrgz_/Documents/PACIFICO/venv/lib/python3.11/site-packages/django/template/base.py", line 906, in _resolve_lookup
    raise VariableDoesNotExist(
django.template.base.VariableDoesNotExist: Failed lookup for key [coporSalarioNeto] in {'auxMonto2': Decimal('14542.91'), 'r1': Decimal('14.00'), 'tasaEstimada': Decimal('9.10'), 'calcComiCierreFinal': Decimal('15.06'), 'auxPlazoPago': 72, 'wrkLetraSinSeguros': Decimal('271.29'), 'wrkLetraSeguro': Decimal('11.45'), 'wrkMontoLetra': Decimal('282.74'), 'montoMensualSeguro': Decimal('0.00'), 'wrkLetraConSeguros': Decimal('282.74'), 'tablaTotalPagos': Decimal('20357.28'), 'nombreCliente': 'asd', 'valorAuto': Decimal('12351.00'), 'abono': Decimal('0.00'), 'salarioBaseMensual': Decimal('1500.00'), 'totalDescuentosLegales': Decimal('263.08'), 'totalDescuentoDirecto': Decimal('350.00'), 'totalPagoVoluntario': Decimal('120.00'), 'salarioNetoActual': Decimal('766.92'), 'salarioNeto': Decimal('484.18'), 'porSalarioNeto': Decimal('32.28'), 'totalIngresosAdicionales': Decimal('0.00'), 'totalIngresosMensualesCompleto': Decimal('1500.00'), 'totalDescuentosLegalesCompleto': Decimal('263.08'), 'salarioNetoActualCompleto': Decimal('766.92'), 'salarioNetoCompleto': Decimal('484.18'), 'porSalarioNetoCompleto': Decimal('32.28'), 'numero_cotizacion': 19}
DEBUG:django.template:Exception while resolving variable 'cosalarioBaseMensual' in template 'fideicomiso_form.html'.
Traceback (most recent call last):
  File "/Users/andresrdrgz_/Documents/PACIFICO/venv/lib/python3.11/site-packages/django/template/base.py", line 883, in _resolve_lookup
    current = current[bit]
              ~~~~~~~^^^^^
KeyError: 'cosalarioBaseMensual'

During handling of the above exception, another exception occurred:

Traceback (most recent call last):
  File "/Users/andresrdrgz_/Documents/PACIFICO/venv/lib/python3.11/site-packages/django/template/base.py", line 893, in _resolve_lookup
    current = getattr(current, bit)
              ^^^^^^^^^^^^^^^^^^^^^
AttributeError: 'dict' object has no attribute 'cosalarioBaseMensual'

During handling of the above exception, another exception occurred:

Traceback (most recent call last):
  File "/Users/andresrdrgz_/Documents/PACIFICO/venv/lib/python3.11/site-packages/django/template/base.py", line 899, in _resolve_lookup
    current = current[int(bit)]
                      ^^^^^^^^
ValueError: invalid literal for int() with base 10: 'cosalarioBaseMensual'

During handling of the above exception, another exception occurred:

Traceback (most recent call last):
  File "/Users/andresrdrgz_/Documents/PACIFICO/venv/lib/python3.11/site-packages/django/template/base.py", line 906, in _resolve_lookup
    raise VariableDoesNotExist(
django.template.base.VariableDoesNotExist: Failed lookup for key [cosalarioBaseMensual] in {'auxMonto2': Decimal('14542.91'), 'r1': Decimal('14.00'), 'tasaEstimada': Decimal('9.10'), 'calcComiCierreFinal': Decimal('15.06'), 'auxPlazoPago': 72, 'wrkLetraSinSeguros': Decimal('271.29'), 'wrkLetraSeguro': Decimal('11.45'), 'wrkMontoLetra': Decimal('282.74'), 'montoMensualSeguro': Decimal('0.00'), 'wrkLetraConSeguros': Decimal('282.74'), 'tablaTotalPagos': Decimal('20357.28'), 'nombreCliente': 'asd', 'valorAuto': Decimal('12351.00'), 'abono': Decimal('0.00'), 'salarioBaseMensual': Decimal('1500.00'), 'totalDescuentosLegales': Decimal('263.08'), 'totalDescuentoDirecto': Decimal('350.00'), 'totalPagoVoluntario': Decimal('120.00'), 'salarioNetoActual': Decimal('766.92'), 'salarioNeto': Decimal('484.18'), 'porSalarioNeto': Decimal('32.28'), 'totalIngresosAdicionales': Decimal('0.00'), 'totalIngresosMensualesCompleto': Decimal('1500.00'), 'totalDescuentosLegalesCompleto': Decimal('263.08'), 'salarioNetoActualCompleto': Decimal('766.92'), 'salarioNetoCompleto': Decimal('484.18'), 'porSalarioNetoCompleto': Decimal('32.28'), 'numero_cotizacion': 19}
DEBUG:django.template:Exception while resolving variable 'cototalIngresosAdicionales' in template 'fideicomiso_form.html'.
Traceback (most recent call last):
  File "/Users/andresrdrgz_/Documents/PACIFICO/venv/lib/python3.11/site-packages/django/template/base.py", line 883, in _resolve_lookup
    current = current[bit]
              ~~~~~~~^^^^^
KeyError: 'cototalIngresosAdicionales'

During handling of the above exception, another exception occurred:

Traceback (most recent call last):
  File "/Users/andresrdrgz_/Documents/PACIFICO/venv/lib/python3.11/site-packages/django/template/base.py", line 893, in _resolve_lookup
    current = getattr(current, bit)
              ^^^^^^^^^^^^^^^^^^^^^
AttributeError: 'dict' object has no attribute 'cototalIngresosAdicionales'

During handling of the above exception, another exception occurred:

Traceback (most recent call last):
  File "/Users/andresrdrgz_/Documents/PACIFICO/venv/lib/python3.11/site-packages/django/template/base.py", line 899, in _resolve_lookup
    current = current[int(bit)]
                      ^^^^^^^^
ValueError: invalid literal for int() with base 10: 'cototalIngresosAdicionales'

During handling of the above exception, another exception occurred:

Traceback (most recent call last):
  File "/Users/andresrdrgz_/Documents/PACIFICO/venv/lib/python3.11/site-packages/django/template/base.py", line 906, in _resolve_lookup
    raise VariableDoesNotExist(
django.template.base.VariableDoesNotExist: Failed lookup for key [cototalIngresosAdicionales] in {'auxMonto2': Decimal('14542.91'), 'r1': Decimal('14.00'), 'tasaEstimada': Decimal('9.10'), 'calcComiCierreFinal': Decimal('15.06'), 'auxPlazoPago': 72, 'wrkLetraSinSeguros': Decimal('271.29'), 'wrkLetraSeguro': Decimal('11.45'), 'wrkMontoLetra': Decimal('282.74'), 'montoMensualSeguro': Decimal('0.00'), 'wrkLetraConSeguros': Decimal('282.74'), 'tablaTotalPagos': Decimal('20357.28'), 'nombreCliente': 'asd', 'valorAuto': Decimal('12351.00'), 'abono': Decimal('0.00'), 'salarioBaseMensual': Decimal('1500.00'), 'totalDescuentosLegales': Decimal('263.08'), 'totalDescuentoDirecto': Decimal('350.00'), 'totalPagoVoluntario': Decimal('120.00'), 'salarioNetoActual': Decimal('766.92'), 'salarioNeto': Decimal('484.18'), 'porSalarioNeto': Decimal('32.28'), 'totalIngresosAdicionales': Decimal('0.00'), 'totalIngresosMensualesCompleto': Decimal('1500.00'), 'totalDescuentosLegalesCompleto': Decimal('263.08'), 'salarioNetoActualCompleto': Decimal('766.92'), 'salarioNetoCompleto': Decimal('484.18'), 'porSalarioNetoCompleto': Decimal('32.28'), 'numero_cotizacion': 19}
DEBUG:django.template:Exception while resolving variable 'cototalIngresosMensualesCompleto' in template 'fideicomiso_form.html'.
Traceback (most recent call last):
  File "/Users/andresrdrgz_/Documents/PACIFICO/venv/lib/python3.11/site-packages/django/template/base.py", line 883, in _resolve_lookup
    current = current[bit]
              ~~~~~~~^^^^^
KeyError: 'cototalIngresosMensualesCompleto'

During handling of the above exception, another exception occurred:

Traceback (most recent call last):
  File "/Users/andresrdrgz_/Documents/PACIFICO/venv/lib/python3.11/site-packages/django/template/base.py", line 893, in _resolve_lookup
    current = getattr(current, bit)
              ^^^^^^^^^^^^^^^^^^^^^
AttributeError: 'dict' object has no attribute 'cototalIngresosMensualesCompleto'

During handling of the above exception, another exception occurred:

Traceback (most recent call last):
  File "/Users/andresrdrgz_/Documents/PACIFICO/venv/lib/python3.11/site-packages/django/template/base.py", line 899, in _resolve_lookup
    current = current[int(bit)]
                      ^^^^^^^^
ValueError: invalid literal for int() with base 10: 'cototalIngresosMensualesCompleto'

During handling of the above exception, another exception occurred:

Traceback (most recent call last):
  File "/Users/andresrdrgz_/Documents/PACIFICO/venv/lib/python3.11/site-packages/django/template/base.py", line 906, in _resolve_lookup
    raise VariableDoesNotExist(
django.template.base.VariableDoesNotExist: Failed lookup for key [cototalIngresosMensualesCompleto] in {'auxMonto2': Decimal('14542.91'), 'r1': Decimal('14.00'), 'tasaEstimada': Decimal('9.10'), 'calcComiCierreFinal': Decimal('15.06'), 'auxPlazoPago': 72, 'wrkLetraSinSeguros': Decimal('271.29'), 'wrkLetraSeguro': Decimal('11.45'), 'wrkMontoLetra': Decimal('282.74'), 'montoMensualSeguro': Decimal('0.00'), 'wrkLetraConSeguros': Decimal('282.74'), 'tablaTotalPagos': Decimal('20357.28'), 'nombreCliente': 'asd', 'valorAuto': Decimal('12351.00'), 'abono': Decimal('0.00'), 'salarioBaseMensual': Decimal('1500.00'), 'totalDescuentosLegales': Decimal('263.08'), 'totalDescuentoDirecto': Decimal('350.00'), 'totalPagoVoluntario': Decimal('120.00'), 'salarioNetoActual': Decimal('766.92'), 'salarioNeto': Decimal('484.18'), 'porSalarioNeto': Decimal('32.28'), 'totalIngresosAdicionales': Decimal('0.00'), 'totalIngresosMensualesCompleto': Decimal('1500.00'), 'totalDescuentosLegalesCompleto': Decimal('263.08'), 'salarioNetoActualCompleto': Decimal('766.92'), 'salarioNetoCompleto': Decimal('484.18'), 'porSalarioNetoCompleto': Decimal('32.28'), 'numero_cotizacion': 19}
DEBUG:django.template:Exception while resolving variable 'cototalDescuentosLegalesCompleto' in template 'fideicomiso_form.html'.
Traceback (most recent call last):
  File "/Users/andresrdrgz_/Documents/PACIFICO/venv/lib/python3.11/site-packages/django/template/base.py", line 883, in _resolve_lookup
    current = current[bit]
              ~~~~~~~^^^^^
KeyError: 'cototalDescuentosLegalesCompleto'

During handling of the above exception, another exception occurred:

Traceback (most recent call last):
  File "/Users/andresrdrgz_/Documents/PACIFICO/venv/lib/python3.11/site-packages/django/template/base.py", line 893, in _resolve_lookup
    current = getattr(current, bit)
              ^^^^^^^^^^^^^^^^^^^^^
AttributeError: 'dict' object has no attribute 'cototalDescuentosLegalesCompleto'

During handling of the above exception, another exception occurred:

Traceback (most recent call last):
  File "/Users/andresrdrgz_/Documents/PACIFICO/venv/lib/python3.11/site-packages/django/template/base.py", line 899, in _resolve_lookup
    current = current[int(bit)]
                      ^^^^^^^^
ValueError: invalid literal for int() with base 10: 'cototalDescuentosLegalesCompleto'

During handling of the above exception, another exception occurred:

Traceback (most recent call last):
  File "/Users/andresrdrgz_/Documents/PACIFICO/venv/lib/python3.11/site-packages/django/template/base.py", line 906, in _resolve_lookup
    raise VariableDoesNotExist(
django.template.base.VariableDoesNotExist: Failed lookup for key [cototalDescuentosLegalesCompleto] in {'auxMonto2': Decimal('14542.91'), 'r1': Decimal('14.00'), 'tasaEstimada': Decimal('9.10'), 'calcComiCierreFinal': Decimal('15.06'), 'auxPlazoPago': 72, 'wrkLetraSinSeguros': Decimal('271.29'), 'wrkLetraSeguro': Decimal('11.45'), 'wrkMontoLetra': Decimal('282.74'), 'montoMensualSeguro': Decimal('0.00'), 'wrkLetraConSeguros': Decimal('282.74'), 'tablaTotalPagos': Decimal('20357.28'), 'nombreCliente': 'asd', 'valorAuto': Decimal('12351.00'), 'abono': Decimal('0.00'), 'salarioBaseMensual': Decimal('1500.00'), 'totalDescuentosLegales': Decimal('263.08'), 'totalDescuentoDirecto': Decimal('350.00'), 'totalPagoVoluntario': Decimal('120.00'), 'salarioNetoActual': Decimal('766.92'), 'salarioNeto': Decimal('484.18'), 'porSalarioNeto': Decimal('32.28'), 'totalIngresosAdicionales': Decimal('0.00'), 'totalIngresosMensualesCompleto': Decimal('1500.00'), 'totalDescuentosLegalesCompleto': Decimal('263.08'), 'salarioNetoActualCompleto': Decimal('766.92'), 'salarioNetoCompleto': Decimal('484.18'), 'porSalarioNetoCompleto': Decimal('32.28'), 'numero_cotizacion': 19}
DEBUG:django.template:Exception while resolving variable 'cototalDescuentoDirecto' in template 'fideicomiso_form.html'.
Traceback (most recent call last):
  File "/Users/andresrdrgz_/Documents/PACIFICO/venv/lib/python3.11/site-packages/django/template/base.py", line 883, in _resolve_lookup
    current = current[bit]
              ~~~~~~~^^^^^
KeyError: 'cototalDescuentoDirecto'

During handling of the above exception, another exception occurred:

Traceback (most recent call last):
  File "/Users/andresrdrgz_/Documents/PACIFICO/venv/lib/python3.11/site-packages/django/template/base.py", line 893, in _resolve_lookup
    current = getattr(current, bit)
              ^^^^^^^^^^^^^^^^^^^^^
AttributeError: 'dict' object has no attribute 'cototalDescuentoDirecto'

During handling of the above exception, another exception occurred:

Traceback (most recent call last):
  File "/Users/andresrdrgz_/Documents/PACIFICO/venv/lib/python3.11/site-packages/django/template/base.py", line 899, in _resolve_lookup
    current = current[int(bit)]
                      ^^^^^^^^
ValueError: invalid literal for int() with base 10: 'cototalDescuentoDirecto'

During handling of the above exception, another exception occurred:

Traceback (most recent call last):
  File "/Users/andresrdrgz_/Documents/PACIFICO/venv/lib/python3.11/site-packages/django/template/base.py", line 906, in _resolve_lookup
    raise VariableDoesNotExist(
django.template.base.VariableDoesNotExist: Failed lookup for key [cototalDescuentoDirecto] in {'auxMonto2': Decimal('14542.91'), 'r1': Decimal('14.00'), 'tasaEstimada': Decimal('9.10'), 'calcComiCierreFinal': Decimal('15.06'), 'auxPlazoPago': 72, 'wrkLetraSinSeguros': Decimal('271.29'), 'wrkLetraSeguro': Decimal('11.45'), 'wrkMontoLetra': Decimal('282.74'), 'montoMensualSeguro': Decimal('0.00'), 'wrkLetraConSeguros': Decimal('282.74'), 'tablaTotalPagos': Decimal('20357.28'), 'nombreCliente': 'asd', 'valorAuto': Decimal('12351.00'), 'abono': Decimal('0.00'), 'salarioBaseMensual': Decimal('1500.00'), 'totalDescuentosLegales': Decimal('263.08'), 'totalDescuentoDirecto': Decimal('350.00'), 'totalPagoVoluntario': Decimal('120.00'), 'salarioNetoActual': Decimal('766.92'), 'salarioNeto': Decimal('484.18'), 'porSalarioNeto': Decimal('32.28'), 'totalIngresosAdicionales': Decimal('0.00'), 'totalIngresosMensualesCompleto': Decimal('1500.00'), 'totalDescuentosLegalesCompleto': Decimal('263.08'), 'salarioNetoActualCompleto': Decimal('766.92'), 'salarioNetoCompleto': Decimal('484.18'), 'porSalarioNetoCompleto': Decimal('32.28'), 'numero_cotizacion': 19}
DEBUG:django.template:Exception while resolving variable 'cototalPagoVoluntario' in template 'fideicomiso_form.html'.
Traceback (most recent call last):
  File "/Users/andresrdrgz_/Documents/PACIFICO/venv/lib/python3.11/site-packages/django/template/base.py", line 883, in _resolve_lookup
    current = current[bit]
              ~~~~~~~^^^^^
KeyError: 'cototalPagoVoluntario'

During handling of the above exception, another exception occurred:

Traceback (most recent call last):
  File "/Users/andresrdrgz_/Documents/PACIFICO/venv/lib/python3.11/site-packages/django/template/base.py", line 893, in _resolve_lookup
    current = getattr(current, bit)
              ^^^^^^^^^^^^^^^^^^^^^
AttributeError: 'dict' object has no attribute 'cototalPagoVoluntario'

During handling of the above exception, another exception occurred:

Traceback (most recent call last):
  File "/Users/andresrdrgz_/Documents/PACIFICO/venv/lib/python3.11/site-packages/django/template/base.py", line 899, in _resolve_lookup
    current = current[int(bit)]
                      ^^^^^^^^
ValueError: invalid literal for int() with base 10: 'cototalPagoVoluntario'

During handling of the above exception, another exception occurred:

Traceback (most recent call last):
  File "/Users/andresrdrgz_/Documents/PACIFICO/venv/lib/python3.11/site-packages/django/template/base.py", line 906, in _resolve_lookup
    raise VariableDoesNotExist(
django.template.base.VariableDoesNotExist: Failed lookup for key [cototalPagoVoluntario] in {'auxMonto2': Decimal('14542.91'), 'r1': Decimal('14.00'), 'tasaEstimada': Decimal('9.10'), 'calcComiCierreFinal': Decimal('15.06'), 'auxPlazoPago': 72, 'wrkLetraSinSeguros': Decimal('271.29'), 'wrkLetraSeguro': Decimal('11.45'), 'wrkMontoLetra': Decimal('282.74'), 'montoMensualSeguro': Decimal('0.00'), 'wrkLetraConSeguros': Decimal('282.74'), 'tablaTotalPagos': Decimal('20357.28'), 'nombreCliente': 'asd', 'valorAuto': Decimal('12351.00'), 'abono': Decimal('0.00'), 'salarioBaseMensual': Decimal('1500.00'), 'totalDescuentosLegales': Decimal('263.08'), 'totalDescuentoDirecto': Decimal('350.00'), 'totalPagoVoluntario': Decimal('120.00'), 'salarioNetoActual': Decimal('766.92'), 'salarioNeto': Decimal('484.18'), 'porSalarioNeto': Decimal('32.28'), 'totalIngresosAdicionales': Decimal('0.00'), 'totalIngresosMensualesCompleto': Decimal('1500.00'), 'totalDescuentosLegalesCompleto': Decimal('263.08'), 'salarioNetoActualCompleto': Decimal('766.92'), 'salarioNetoCompleto': Decimal('484.18'), 'porSalarioNetoCompleto': Decimal('32.28'), 'numero_cotizacion': 19}
DEBUG:django.template:Exception while resolving variable 'cosalarioNetoActualCompleto' in template 'fideicomiso_form.html'.
Traceback (most recent call last):
  File "/Users/andresrdrgz_/Documents/PACIFICO/venv/lib/python3.11/site-packages/django/template/base.py", line 883, in _resolve_lookup
    current = current[bit]
              ~~~~~~~^^^^^
KeyError: 'cosalarioNetoActualCompleto'

During handling of the above exception, another exception occurred:

Traceback (most recent call last):
  File "/Users/andresrdrgz_/Documents/PACIFICO/venv/lib/python3.11/site-packages/django/template/base.py", line 893, in _resolve_lookup
    current = getattr(current, bit)
              ^^^^^^^^^^^^^^^^^^^^^
AttributeError: 'dict' object has no attribute 'cosalarioNetoActualCompleto'

During handling of the above exception, another exception occurred:

Traceback (most recent call last):
  File "/Users/andresrdrgz_/Documents/PACIFICO/venv/lib/python3.11/site-packages/django/template/base.py", line 899, in _resolve_lookup
    current = current[int(bit)]
                      ^^^^^^^^
ValueError: invalid literal for int() with base 10: 'cosalarioNetoActualCompleto'

During handling of the above exception, another exception occurred:

Traceback (most recent call last):
  File "/Users/andresrdrgz_/Documents/PACIFICO/venv/lib/python3.11/site-packages/django/template/base.py", line 906, in _resolve_lookup
    raise VariableDoesNotExist(
django.template.base.VariableDoesNotExist: Failed lookup for key [cosalarioNetoActualCompleto] in {'auxMonto2': Decimal('14542.91'), 'r1': Decimal('14.00'), 'tasaEstimada': Decimal('9.10'), 'calcComiCierreFinal': Decimal('15.06'), 'auxPlazoPago': 72, 'wrkLetraSinSeguros': Decimal('271.29'), 'wrkLetraSeguro': Decimal('11.45'), 'wrkMontoLetra': Decimal('282.74'), 'montoMensualSeguro': Decimal('0.00'), 'wrkLetraConSeguros': Decimal('282.74'), 'tablaTotalPagos': Decimal('20357.28'), 'nombreCliente': 'asd', 'valorAuto': Decimal('12351.00'), 'abono': Decimal('0.00'), 'salarioBaseMensual': Decimal('1500.00'), 'totalDescuentosLegales': Decimal('263.08'), 'totalDescuentoDirecto': Decimal('350.00'), 'totalPagoVoluntario': Decimal('120.00'), 'salarioNetoActual': Decimal('766.92'), 'salarioNeto': Decimal('484.18'), 'porSalarioNeto': Decimal('32.28'), 'totalIngresosAdicionales': Decimal('0.00'), 'totalIngresosMensualesCompleto': Decimal('1500.00'), 'totalDescuentosLegalesCompleto': Decimal('263.08'), 'salarioNetoActualCompleto': Decimal('766.92'), 'salarioNetoCompleto': Decimal('484.18'), 'porSalarioNetoCompleto': Decimal('32.28'), 'numero_cotizacion': 19}
DEBUG:django.template:Exception while resolving variable 'cowrkLetraConSeguros' in template 'fideicomiso_form.html'.
Traceback (most recent call last):
  File "/Users/andresrdrgz_/Documents/PACIFICO/venv/lib/python3.11/site-packages/django/template/base.py", line 883, in _resolve_lookup
    current = current[bit]
              ~~~~~~~^^^^^
KeyError: 'cowrkLetraConSeguros'

During handling of the above exception, another exception occurred:

Traceback (most recent call last):
  File "/Users/andresrdrgz_/Documents/PACIFICO/venv/lib/python3.11/site-packages/django/template/base.py", line 893, in _resolve_lookup
    current = getattr(current, bit)
              ^^^^^^^^^^^^^^^^^^^^^
AttributeError: 'dict' object has no attribute 'cowrkLetraConSeguros'

During handling of the above exception, another exception occurred:

Traceback (most recent call last):
  File "/Users/andresrdrgz_/Documents/PACIFICO/venv/lib/python3.11/site-packages/django/template/base.py", line 899, in _resolve_lookup
    current = current[int(bit)]
                      ^^^^^^^^
ValueError: invalid literal for int() with base 10: 'cowrkLetraConSeguros'

During handling of the above exception, another exception occurred:

Traceback (most recent call last):
  File "/Users/andresrdrgz_/Documents/PACIFICO/venv/lib/python3.11/site-packages/django/template/base.py", line 906, in _resolve_lookup
    raise VariableDoesNotExist(
django.template.base.VariableDoesNotExist: Failed lookup for key [cowrkLetraConSeguros] in {'auxMonto2': Decimal('14542.91'), 'r1': Decimal('14.00'), 'tasaEstimada': Decimal('9.10'), 'calcComiCierreFinal': Decimal('15.06'), 'auxPlazoPago': 72, 'wrkLetraSinSeguros': Decimal('271.29'), 'wrkLetraSeguro': Decimal('11.45'), 'wrkMontoLetra': Decimal('282.74'), 'montoMensualSeguro': Decimal('0.00'), 'wrkLetraConSeguros': Decimal('282.74'), 'tablaTotalPagos': Decimal('20357.28'), 'nombreCliente': 'asd', 'valorAuto': Decimal('12351.00'), 'abono': Decimal('0.00'), 'salarioBaseMensual': Decimal('1500.00'), 'totalDescuentosLegales': Decimal('263.08'), 'totalDescuentoDirecto': Decimal('350.00'), 'totalPagoVoluntario': Decimal('120.00'), 'salarioNetoActual': Decimal('766.92'), 'salarioNeto': Decimal('484.18'), 'porSalarioNeto': Decimal('32.28'), 'totalIngresosAdicionales': Decimal('0.00'), 'totalIngresosMensualesCompleto': Decimal('1500.00'), 'totalDescuentosLegalesCompleto': Decimal('263.08'), 'salarioNetoActualCompleto': Decimal('766.92'), 'salarioNetoCompleto': Decimal('484.18'), 'porSalarioNetoCompleto': Decimal('32.28'), 'numero_cotizacion': 19}
DEBUG:django.template:Exception while resolving variable 'cosalarioNetoCompleto' in template 'fideicomiso_form.html'.
Traceback (most recent call last):
  File "/Users/andresrdrgz_/Documents/PACIFICO/venv/lib/python3.11/site-packages/django/template/base.py", line 883, in _resolve_lookup
    current = current[bit]
              ~~~~~~~^^^^^
KeyError: 'cosalarioNetoCompleto'

During handling of the above exception, another exception occurred:

Traceback (most recent call last):
  File "/Users/andresrdrgz_/Documents/PACIFICO/venv/lib/python3.11/site-packages/django/template/base.py", line 893, in _resolve_lookup
    current = getattr(current, bit)
              ^^^^^^^^^^^^^^^^^^^^^
AttributeError: 'dict' object has no attribute 'cosalarioNetoCompleto'

During handling of the above exception, another exception occurred:

Traceback (most recent call last):
  File "/Users/andresrdrgz_/Documents/PACIFICO/venv/lib/python3.11/site-packages/django/template/base.py", line 899, in _resolve_lookup
    current = current[int(bit)]
                      ^^^^^^^^
ValueError: invalid literal for int() with base 10: 'cosalarioNetoCompleto'

During handling of the above exception, another exception occurred:

Traceback (most recent call last):
  File "/Users/andresrdrgz_/Documents/PACIFICO/venv/lib/python3.11/site-packages/django/template/base.py", line 906, in _resolve_lookup
    raise VariableDoesNotExist(
django.template.base.VariableDoesNotExist: Failed lookup for key [cosalarioNetoCompleto] in {'auxMonto2': Decimal('14542.91'), 'r1': Decimal('14.00'), 'tasaEstimada': Decimal('9.10'), 'calcComiCierreFinal': Decimal('15.06'), 'auxPlazoPago': 72, 'wrkLetraSinSeguros': Decimal('271.29'), 'wrkLetraSeguro': Decimal('11.45'), 'wrkMontoLetra': Decimal('282.74'), 'montoMensualSeguro': Decimal('0.00'), 'wrkLetraConSeguros': Decimal('282.74'), 'tablaTotalPagos': Decimal('20357.28'), 'nombreCliente': 'asd', 'valorAuto': Decimal('12351.00'), 'abono': Decimal('0.00'), 'salarioBaseMensual': Decimal('1500.00'), 'totalDescuentosLegales': Decimal('263.08'), 'totalDescuentoDirecto': Decimal('350.00'), 'totalPagoVoluntario': Decimal('120.00'), 'salarioNetoActual': Decimal('766.92'), 'salarioNeto': Decimal('484.18'), 'porSalarioNeto': Decimal('32.28'), 'totalIngresosAdicionales': Decimal('0.00'), 'totalIngresosMensualesCompleto': Decimal('1500.00'), 'totalDescuentosLegalesCompleto': Decimal('263.08'), 'salarioNetoActualCompleto': Decimal('766.92'), 'salarioNetoCompleto': Decimal('484.18'), 'porSalarioNetoCompleto': Decimal('32.28'), 'numero_cotizacion': 19}
DEBUG:django.template:Exception while resolving variable 'coporSalarioNetoCompleto' in template 'fideicomiso_form.html'.
Traceback (most recent call last):
  File "/Users/andresrdrgz_/Documents/PACIFICO/venv/lib/python3.11/site-packages/django/template/base.py", line 883, in _resolve_lookup
    current = current[bit]
              ~~~~~~~^^^^^
KeyError: 'coporSalarioNetoCompleto'

During handling of the above exception, another exception occurred:

Traceback (most recent call last):
  File "/Users/andresrdrgz_/Documents/PACIFICO/venv/lib/python3.11/site-packages/django/template/base.py", line 893, in _resolve_lookup
    current = getattr(current, bit)
              ^^^^^^^^^^^^^^^^^^^^^
AttributeError: 'dict' object has no attribute 'coporSalarioNetoCompleto'

During handling of the above exception, another exception occurred:

Traceback (most recent call last):
  File "/Users/andresrdrgz_/Documents/PACIFICO/venv/lib/python3.11/site-packages/django/template/base.py", line 899, in _resolve_lookup
    current = current[int(bit)]
                      ^^^^^^^^
ValueError: invalid literal for int() with base 10: 'coporSalarioNetoCompleto'

During handling of the above exception, another exception occurred:

Traceback (most recent call last):
  File "/Users/andresrdrgz_/Documents/PACIFICO/venv/lib/python3.11/site-packages/django/template/base.py", line 906, in _resolve_lookup
    raise VariableDoesNotExist(
django.template.base.VariableDoesNotExist: Failed lookup for key [coporSalarioNetoCompleto] in {'auxMonto2': Decimal('14542.91'), 'r1': Decimal('14.00'), 'tasaEstimada': Decimal('9.10'), 'calcComiCierreFinal': Decimal('15.06'), 'auxPlazoPago': 72, 'wrkLetraSinSeguros': Decimal('271.29'), 'wrkLetraSeguro': Decimal('11.45'), 'wrkMontoLetra': Decimal('282.74'), 'montoMensualSeguro': Decimal('0.00'), 'wrkLetraConSeguros': Decimal('282.74'), 'tablaTotalPagos': Decimal('20357.28'), 'nombreCliente': 'asd', 'valorAuto': Decimal('12351.00'), 'abono': Decimal('0.00'), 'salarioBaseMensual': Decimal('1500.00'), 'totalDescuentosLegales': Decimal('263.08'), 'totalDescuentoDirecto': Decimal('350.00'), 'totalPagoVoluntario': Decimal('120.00'), 'salarioNetoActual': Decimal('766.92'), 'salarioNeto': Decimal('484.18'), 'porSalarioNeto': Decimal('32.28'), 'totalIngresosAdicionales': Decimal('0.00'), 'totalIngresosMensualesCompleto': Decimal('1500.00'), 'totalDescuentosLegalesCompleto': Decimal('263.08'), 'salarioNetoActualCompleto': Decimal('766.92'), 'salarioNetoCompleto': Decimal('484.18'), 'porSalarioNetoCompleto': Decimal('32.28'), 'numero_cotizacion': 19}
DEBUG:django.db.backends:(0.000) SELECT "pacifico_aseguradora"."id", "pacifico_aseguradora"."descripcion", "pacifico_aseguradora"."codigo" FROM "pacifico_aseguradora"; args=(); alias=default
DEBUG:django.template:Exception while resolving variable 'lineaAuto' in template 'fideicomiso_form.html'.
Traceback (most recent call last):
  File "/Users/andresrdrgz_/Documents/PACIFICO/venv/lib/python3.11/site-packages/django/template/base.py", line 883, in _resolve_lookup
    current = current[bit]
              ~~~~~~~^^^^^
KeyError: 'lineaAuto'

During handling of the above exception, another exception occurred:

Traceback (most recent call last):
  File "/Users/andresrdrgz_/Documents/PACIFICO/venv/lib/python3.11/site-packages/django/template/base.py", line 893, in _resolve_lookup
    current = getattr(current, bit)
              ^^^^^^^^^^^^^^^^^^^^^
AttributeError: 'dict' object has no attribute 'lineaAuto'

During handling of the above exception, another exception occurred:

Traceback (most recent call last):
  File "/Users/andresrdrgz_/Documents/PACIFICO/venv/lib/python3.11/site-packages/django/template/base.py", line 899, in _resolve_lookup
    current = current[int(bit)]
                      ^^^^^^^^
ValueError: invalid literal for int() with base 10: 'lineaAuto'

During handling of the above exception, another exception occurred:

Traceback (most recent call last):
  File "/Users/andresrdrgz_/Documents/PACIFICO/venv/lib/python3.11/site-packages/django/template/base.py", line 906, in _resolve_lookup
    raise VariableDoesNotExist(
django.template.base.VariableDoesNotExist: Failed lookup for key [lineaAuto] in {'auxMonto2': Decimal('14542.91'), 'r1': Decimal('14.00'), 'tasaEstimada': Decimal('9.10'), 'calcComiCierreFinal': Decimal('15.06'), 'auxPlazoPago': 72, 'wrkLetraSinSeguros': Decimal('271.29'), 'wrkLetraSeguro': Decimal('11.45'), 'wrkMontoLetra': Decimal('282.74'), 'montoMensualSeguro': Decimal('0.00'), 'wrkLetraConSeguros': Decimal('282.74'), 'tablaTotalPagos': Decimal('20357.28'), 'nombreCliente': 'asd', 'valorAuto': Decimal('12351.00'), 'abono': Decimal('0.00'), 'salarioBaseMensual': Decimal('1500.00'), 'totalDescuentosLegales': Decimal('263.08'), 'totalDescuentoDirecto': Decimal('350.00'), 'totalPagoVoluntario': Decimal('120.00'), 'salarioNetoActual': Decimal('766.92'), 'salarioNeto': Decimal('484.18'), 'porSalarioNeto': Decimal('32.28'), 'totalIngresosAdicionales': Decimal('0.00'), 'totalIngresosMensualesCompleto': Decimal('1500.00'), 'totalDescuentosLegalesCompleto': Decimal('263.08'), 'salarioNetoActualCompleto': Decimal('766.92'), 'salarioNetoCompleto': Decimal('484.18'), 'porSalarioNetoCompleto': Decimal('32.28'), 'numero_cotizacion': 19}
DEBUG:django.template:Exception while resolving variable 'lineaAuto' in template 'fideicomiso_form.html'.
Traceback (most recent call last):
  File "/Users/andresrdrgz_/Documents/PACIFICO/venv/lib/python3.11/site-packages/django/template/base.py", line 883, in _resolve_lookup
    current = current[bit]
              ~~~~~~~^^^^^
KeyError: 'lineaAuto'

During handling of the above exception, another exception occurred:

Traceback (most recent call last):
  File "/Users/andresrdrgz_/Documents/PACIFICO/venv/lib/python3.11/site-packages/django/template/base.py", line 893, in _resolve_lookup
    current = getattr(current, bit)
              ^^^^^^^^^^^^^^^^^^^^^
AttributeError: 'dict' object has no attribute 'lineaAuto'

During handling of the above exception, another exception occurred:

Traceback (most recent call last):
  File "/Users/andresrdrgz_/Documents/PACIFICO/venv/lib/python3.11/site-packages/django/template/base.py", line 899, in _resolve_lookup
    current = current[int(bit)]
                      ^^^^^^^^
ValueError: invalid literal for int() with base 10: 'lineaAuto'

During handling of the above exception, another exception occurred:

Traceback (most recent call last):
  File "/Users/andresrdrgz_/Documents/PACIFICO/venv/lib/python3.11/site-packages/django/template/base.py", line 906, in _resolve_lookup
    raise VariableDoesNotExist(
django.template.base.VariableDoesNotExist: Failed lookup for key [lineaAuto] in {'auxMonto2': Decimal('14542.91'), 'r1': Decimal('14.00'), 'tasaEstimada': Decimal('9.10'), 'calcComiCierreFinal': Decimal('15.06'), 'auxPlazoPago': 72, 'wrkLetraSinSeguros': Decimal('271.29'), 'wrkLetraSeguro': Decimal('11.45'), 'wrkMontoLetra': Decimal('282.74'), 'montoMensualSeguro': Decimal('0.00'), 'wrkLetraConSeguros': Decimal('282.74'), 'tablaTotalPagos': Decimal('20357.28'), 'nombreCliente': 'asd', 'valorAuto': Decimal('12351.00'), 'abono': Decimal('0.00'), 'salarioBaseMensual': Decimal('1500.00'), 'totalDescuentosLegales': Decimal('263.08'), 'totalDescuentoDirecto': Decimal('350.00'), 'totalPagoVoluntario': Decimal('120.00'), 'salarioNetoActual': Decimal('766.92'), 'salarioNeto': Decimal('484.18'), 'porSalarioNeto': Decimal('32.28'), 'totalIngresosAdicionales': Decimal('0.00'), 'totalIngresosMensualesCompleto': Decimal('1500.00'), 'totalDescuentosLegalesCompleto': Decimal('263.08'), 'salarioNetoActualCompleto': Decimal('766.92'), 'salarioNetoCompleto': Decimal('484.18'), 'porSalarioNetoCompleto': Decimal('32.28'), 'numero_cotizacion': 19}
INFO:django.server:"POST /cotizacion/19/ HTTP/1.1" 200 187384
DEBUG:django.utils.autoreload:File /Users/andresrdrgz_/Documents/PACIFICO/venv/lib/python3.11/site-packages/django/contrib/messages/context_processors.py first seen with mtime 1732569332.500866
DEBUG:django.utils.autoreload:File /Users/andresrdrgz_/Documents/PACIFICO/venv/lib/python3.11/site-packages/django/conf/locale/en/__init__.py first seen with mtime 1732569332.0690286
DEBUG:django.utils.autoreload:File /Users/andresrdrgz_/Documents/PACIFICO/venv/lib/python3.11/site-packages/django/contrib/sessions/serializers.py first seen with mtime 1732569332.5685349
DEBUG:django.utils.autoreload:File /Users/andresrdrgz_/Documents/PACIFICO/venv/lib/python3.11/site-packages/django/contrib/messages/storage/fallback.py first seen with mtime 1732569332.5018916
DEBUG:django.utils.autoreload:File /Users/andresrdrgz_/Documents/PACIFICO/venv/lib/python3.11/site-packages/django/contrib/messages/storage/cookie.py first seen with mtime 1732569332.5017526
DEBUG:django.utils.autoreload:File /Users/andresrdrgz_/anaconda3/lib/python3.11/_strptime.py first seen with mtime 1681948558.9095042
DEBUG:django.utils.autoreload:File /Users/andresrdrgz_/Documents/PACIFICO/venv/lib/python3.11/site-packages/django/template/context_processors.py first seen with mtime 1732569332.7133355
DEBUG:django.utils.autoreload:File /Users/andresrdrgz_/Documents/PACIFICO/venv/lib/python3.11/site-packages/django/contrib/auth/context_processors.py first seen with mtime 1732569332.2745264
DEBUG:django.utils.autoreload:File /Users/andresrdrgz_/Documents/PACIFICO/venv/lib/python3.11/site-packages/django/conf/locale/en/formats.py first seen with mtime 1732569332.0692546
DEBUG:django.utils.autoreload:File /Users/andresrdrgz_/Documents/PACIFICO/venv/lib/python3.11/site-packages/django/contrib/messages/storage/session.py first seen with mtime 1732569332.5019946
DEBUG:django.utils.autoreload:File /Users/andresrdrgz_/Documents/PACIFICO/financiera/pacifico/views.py previous mtime: 1736374219.3190653, current mtime: 1736374333.847807
DEBUG:django.utils.autoreload:/Users/andresrdrgz_/Documents/PACIFICO/financiera/pacifico/views.py notified as changed. Signal results: [(<function template_changed at 0x103164f40>, None), (<function translation_file_changed at 0x103a6dbc0>, None)].
INFO:django.utils.autoreload:/Users/andresrdrgz_/Documents/PACIFICO/financiera/pacifico/views.py changed, reloading.
