ERROR:root:unsupported operand type(s) for +: 'float' and 'NoneType'
DEBUG:django.db.backends:(0.000) SELECT "pacifico_aseguradora"."id", "pacifico_aseguradora"."descripcion", "pacifico_aseguradora"."codigo" FROM "pacifico_aseguradora"; args=(); alias=default
DEBUG:django.template:Exception while resolving variable 'lineaAuto' in template 'fideicomiso_form.html'.
Traceback (most recent call last):
  File "/Users/andresrdrgz_/Documents/PACIFICO/venv/lib/python3.11/site-packages/django/template/base.py", line 883, in _resolve_lookup
    current = current[bit]
              ~~~~~~~^^^^^
KeyError: 'lineaAuto'

During handling of the above exception, another exception occurred:

Traceback (most recent call last):
  File "/Users/andresrdrgz_/Documents/PACIFICO/venv/lib/python3.11/site-packages/django/template/base.py", line 893, in _resolve_lookup
    current = getattr(current, bit)
              ^^^^^^^^^^^^^^^^^^^^^
AttributeError: 'dict' object has no attribute 'lineaAuto'

During handling of the above exception, another exception occurred:

Traceback (most recent call last):
  File "/Users/andresrdrgz_/Documents/PACIFICO/venv/lib/python3.11/site-packages/django/template/base.py", line 899, in _resolve_lookup
    current = current[int(bit)]
                      ^^^^^^^^
ValueError: invalid literal for int() with base 10: 'lineaAuto'

During handling of the above exception, another exception occurred:

Traceback (most recent call last):
  File "/Users/andresrdrgz_/Documents/PACIFICO/venv/lib/python3.11/site-packages/django/template/base.py", line 906, in _resolve_lookup
    raise VariableDoesNotExist(
django.template.base.VariableDoesNotExist: Failed lookup for key [lineaAuto] in {'auxMonto2': Decimal('14542.91'), 'numero_cotizacion': 21, 'r1': Decimal('14.00'), 'tasaEstimada': Decimal('9.10'), 'calcComiCierreFinal': Decimal('15.06'), 'auxPlazoPago': 72, 'wrkLetraSinSeguros': Decimal('271.29'), 'wrkLetraSeguro': Decimal('11.45'), 'wrkMontoLetra': Decimal('282.74'), 'montoMensualSeguro': Decimal('0.00'), 'wrkLetraConSeguros': Decimal('282.74'), 'tablaTotalPagos': Decimal('20357.28'), 'nombreCliente': 'asd', 'valorAuto': Decimal('12351.00'), 'abono': Decimal('0.00'), 'salarioBaseMensual': Decimal('1500.00'), 'totalDescuentosLegales': Decimal('263.08'), 'totalDescuentoDirecto': Decimal('350.00'), 'totalPagoVoluntario': Decimal('120.00'), 'salarioNetoActual': Decimal('766.92'), 'salarioNeto': Decimal('484.18'), 'porSalarioNeto': Decimal('32.28'), 'totalIngresosAdicionales': Decimal('0.00'), 'totalIngresosMensualesCompleto': Decimal('1500.00'), 'totalDescuentosLegalesCompleto': Decimal('263.08'), 'salarioNetoActualCompleto': Decimal('766.92'), 'salarioNetoCompleto': Decimal('484.18'), 'porSalarioNetoCompleto': Decimal('32.28'), 'cosalarioBaseMensual': Decimal('1200.00'), 'cototalDescuentosLegales': Decimal('185.08'), 'cototalDescuentoDirecto': Decimal('590.00'), 'cototalPagoVoluntario': Decimal('2100.00'), 'cosalarioNetoActual': Decimal('-1675.08'), 'cosalarioNeto': Decimal('-1957.82'), 'coporSalarioNeto': Decimal('-163.15'), 'cototalIngresosAdicionales': Decimal('140.00'), 'cototalIngresosMensualesCompleto': Decimal('1340.00'), 'cototalDescuentosLegalesCompleto': Decimal('221.48'), 'cosalarioNetoActualCompleto': Decimal('-1571.48'), 'cosalarioNetoCompleto': Decimal('-1854.22'), 'coporSalarioNetoCompleto': Decimal('-138.37')}
DEBUG:django.template:Exception while resolving variable 'lineaAuto' in template 'fideicomiso_form.html'.
Traceback (most recent call last):
  File "/Users/andresrdrgz_/Documents/PACIFICO/venv/lib/python3.11/site-packages/django/template/base.py", line 883, in _resolve_lookup
    current = current[bit]
              ~~~~~~~^^^^^
KeyError: 'lineaAuto'

During handling of the above exception, another exception occurred:

Traceback (most recent call last):
  File "/Users/andresrdrgz_/Documents/PACIFICO/venv/lib/python3.11/site-packages/django/template/base.py", line 893, in _resolve_lookup
    current = getattr(current, bit)
              ^^^^^^^^^^^^^^^^^^^^^
AttributeError: 'dict' object has no attribute 'lineaAuto'

During handling of the above exception, another exception occurred:

Traceback (most recent call last):
  File "/Users/andresrdrgz_/Documents/PACIFICO/venv/lib/python3.11/site-packages/django/template/base.py", line 899, in _resolve_lookup
    current = current[int(bit)]
                      ^^^^^^^^
ValueError: invalid literal for int() with base 10: 'lineaAuto'

During handling of the above exception, another exception occurred:

Traceback (most recent call last):
  File "/Users/andresrdrgz_/Documents/PACIFICO/venv/lib/python3.11/site-packages/django/template/base.py", line 906, in _resolve_lookup
    raise VariableDoesNotExist(
django.template.base.VariableDoesNotExist: Failed lookup for key [lineaAuto] in {'auxMonto2': Decimal('14542.91'), 'numero_cotizacion': 21, 'r1': Decimal('14.00'), 'tasaEstimada': Decimal('9.10'), 'calcComiCierreFinal': Decimal('15.06'), 'auxPlazoPago': 72, 'wrkLetraSinSeguros': Decimal('271.29'), 'wrkLetraSeguro': Decimal('11.45'), 'wrkMontoLetra': Decimal('282.74'), 'montoMensualSeguro': Decimal('0.00'), 'wrkLetraConSeguros': Decimal('282.74'), 'tablaTotalPagos': Decimal('20357.28'), 'nombreCliente': 'asd', 'valorAuto': Decimal('12351.00'), 'abono': Decimal('0.00'), 'salarioBaseMensual': Decimal('1500.00'), 'totalDescuentosLegales': Decimal('263.08'), 'totalDescuentoDirecto': Decimal('350.00'), 'totalPagoVoluntario': Decimal('120.00'), 'salarioNetoActual': Decimal('766.92'), 'salarioNeto': Decimal('484.18'), 'porSalarioNeto': Decimal('32.28'), 'totalIngresosAdicionales': Decimal('0.00'), 'totalIngresosMensualesCompleto': Decimal('1500.00'), 'totalDescuentosLegalesCompleto': Decimal('263.08'), 'salarioNetoActualCompleto': Decimal('766.92'), 'salarioNetoCompleto': Decimal('484.18'), 'porSalarioNetoCompleto': Decimal('32.28'), 'cosalarioBaseMensual': Decimal('1200.00'), 'cototalDescuentosLegales': Decimal('185.08'), 'cototalDescuentoDirecto': Decimal('590.00'), 'cototalPagoVoluntario': Decimal('2100.00'), 'cosalarioNetoActual': Decimal('-1675.08'), 'cosalarioNeto': Decimal('-1957.82'), 'coporSalarioNeto': Decimal('-163.15'), 'cototalIngresosAdicionales': Decimal('140.00'), 'cototalIngresosMensualesCompleto': Decimal('1340.00'), 'cototalDescuentosLegalesCompleto': Decimal('221.48'), 'cosalarioNetoActualCompleto': Decimal('-1571.48'), 'cosalarioNetoCompleto': Decimal('-1854.22'), 'coporSalarioNetoCompleto': Decimal('-138.37')}
INFO:django.server:"POST /cotizacion/21/ HTTP/1.1" 200 187509
DEBUG:django.utils.autoreload:File /Users/andresrdrgz_/Documents/PACIFICO/venv/lib/python3.11/site-packages/django/contrib/messages/storage/session.py first seen with mtime 1732569332.5019946
DEBUG:django.utils.autoreload:File /Users/andresrdrgz_/anaconda3/lib/python3.11/_strptime.py first seen with mtime 1681948558.9095042
DEBUG:django.utils.autoreload:File /Users/andresrdrgz_/Documents/PACIFICO/venv/lib/python3.11/site-packages/django/contrib/messages/storage/fallback.py first seen with mtime 1732569332.5018916
DEBUG:django.utils.autoreload:File /Users/andresrdrgz_/Documents/PACIFICO/venv/lib/python3.11/site-packages/django/contrib/messages/storage/cookie.py first seen with mtime 1732569332.5017526
DEBUG:django.utils.autoreload:File /Users/andresrdrgz_/Documents/PACIFICO/venv/lib/python3.11/site-packages/django/conf/locale/en/__init__.py first seen with mtime 1732569332.0690286
DEBUG:django.utils.autoreload:File /Users/andresrdrgz_/Documents/PACIFICO/venv/lib/python3.11/site-packages/django/conf/locale/en/formats.py first seen with mtime 1732569332.0692546
DEBUG:django.utils.autoreload:File /Users/andresrdrgz_/Documents/PACIFICO/venv/lib/python3.11/site-packages/django/contrib/sessions/serializers.py first seen with mtime 1732569332.5685349
DEBUG:django.utils.autoreload:File /Users/andresrdrgz_/Documents/PACIFICO/venv/lib/python3.11/site-packages/django/contrib/messages/context_processors.py first seen with mtime 1732569332.500866
DEBUG:django.utils.autoreload:File /Users/andresrdrgz_/Documents/PACIFICO/venv/lib/python3.11/site-packages/django/template/context_processors.py first seen with mtime 1732569332.7133355
DEBUG:django.utils.autoreload:File /Users/andresrdrgz_/Documents/PACIFICO/venv/lib/python3.11/site-packages/django/contrib/auth/context_processors.py first seen with mtime 1732569332.2745264
DEBUG:django.utils.autoreload:File /Users/andresrdrgz_/Documents/PACIFICO/financiera/pacifico/analisisConsulta/nivelEndeudamiento.py previous mtime: 1734639555.51446, current mtime: 1736375078.8490212
DEBUG:django.utils.autoreload:/Users/andresrdrgz_/Documents/PACIFICO/financiera/pacifico/analisisConsulta/nivelEndeudamiento.py notified as changed. Signal results: [(<function template_changed at 0x104758f40>, None), (<function translation_file_changed at 0x1062bdbc0>, None)].
INFO:django.utils.autoreload:/Users/andresrdrgz_/Documents/PACIFICO/financiera/pacifico/analisisConsulta/nivelEndeudamiento.py changed, reloading.
