ERROR:root:set_calculated_values() takes 3 positional arguments but 6 were given
DEBUG:django.db.backends:(0.000) SELECT "pacifico_aseguradora"."id", "pacifico_aseguradora"."descripcion", "pacifico_aseguradora"."codigo" FROM "pacifico_aseguradora"; args=(); alias=default
DEBUG:django.template:Exception while resolving variable 'lineaAuto' in template 'fideicomiso_form.html'.
Traceback (most recent call last):
  File "/Users/andresrdrgz_/Documents/PACIFICO/venv/lib/python3.11/site-packages/django/template/base.py", line 883, in _resolve_lookup
    current = current[bit]
              ~~~~~~~^^^^^
KeyError: 'lineaAuto'

During handling of the above exception, another exception occurred:

Traceback (most recent call last):
  File "/Users/andresrdrgz_/Documents/PACIFICO/venv/lib/python3.11/site-packages/django/template/base.py", line 893, in _resolve_lookup
    current = getattr(current, bit)
              ^^^^^^^^^^^^^^^^^^^^^
AttributeError: 'dict' object has no attribute 'lineaAuto'

During handling of the above exception, another exception occurred:

Traceback (most recent call last):
  File "/Users/andresrdrgz_/Documents/PACIFICO/venv/lib/python3.11/site-packages/django/template/base.py", line 899, in _resolve_lookup
    current = current[int(bit)]
                      ^^^^^^^^
ValueError: invalid literal for int() with base 10: 'lineaAuto'

During handling of the above exception, another exception occurred:

Traceback (most recent call last):
  File "/Users/andresrdrgz_/Documents/PACIFICO/venv/lib/python3.11/site-packages/django/template/base.py", line 906, in _resolve_lookup
    raise VariableDoesNotExist(
django.template.base.VariableDoesNotExist: Failed lookup for key [lineaAuto] in {'auxMonto2': Decimal('34925.43'), 'numero_cotizacion': 68, 'r1': Decimal('13.00'), 'tasaEstimada': Decimal('9.50'), 'calcComiCierreFinal': Decimal('13.84'), 'auxPlazoPago': 96, 'wrkLetraSinSeguros': Decimal('541.60'), 'wrkLetraSeguro': Decimal('27.50'), 'wrkMontoLetra': Decimal('569.10'), 'montoMensualSeguro': Decimal('0.00'), 'wrkLetraConSeguros': Decimal('569.10'), 'tablaTotalPagos': Decimal('54633.60'), 'nombreCliente': 'hasd', 'valorAuto': Decimal('35400.00'), 'abono': Decimal('5310.00'), 'salarioBaseMensual': Decimal('0.00'), 'totalDescuentosLegales': Decimal('0.00'), 'totalDescuentoDirecto': Decimal('0.00'), 'totalPagoVoluntario': Decimal('0.00'), 'salarioNetoActual': Decimal('0.00'), 'salarioNeto': Decimal('-569.10'), 'porSalarioNeto': Decimal('0.00'), 'totalIngresosAdicionales': Decimal('0.00'), 'totalIngresosMensualesCompleto': Decimal('0.00'), 'totalDescuentosLegalesCompleto': Decimal('0.00'), 'salarioNetoActualCompleto': Decimal('0.00'), 'salarioNetoCompleto': Decimal('-569.10'), 'porSalarioNetoCompleto': Decimal('0.00'), 'cosalarioBaseMensual': None, 'cototalDescuentosLegales': None, 'cototalDescuentoDirecto': None, 'cototalPagoVoluntario': None, 'cosalarioNetoActual': None, 'cosalarioNeto': None, 'coporSalarioNeto': None, 'cototalIngresosAdicionales': Decimal('0.00'), 'cototalIngresosMensualesCompleto': None, 'cototalDescuentosLegalesCompleto': None, 'cosalarioNetoActualCompleto': None, 'cosalarioNetoCompleto': None, 'coporSalarioNetoCompleto': None, 'porcentajeLetraSeguro': 0, 'coporcentajeLetraSeguro': 0, 'porcentajeLetraSeguroCompleto': 0, 'coporcentajeLetraSeguroCompleto': 0, 'familiarSalarioBaseMensual': 0, 'familiarSalarioNeto': Decimal('-569.10'), 'familiarporNetoActual': 0, 'familiarpoSalarioNeto': 0, 'familiarNetoActualCompleto': 0, 'familiarporNetoActualCompleto': 0, 'familiarSalarioNetoCompleto': Decimal('-569.10'), 'familiarporSalarioNeto': 0}
DEBUG:django.template:Exception while resolving variable 'lineaAuto' in template 'fideicomiso_form.html'.
Traceback (most recent call last):
  File "/Users/andresrdrgz_/Documents/PACIFICO/venv/lib/python3.11/site-packages/django/template/base.py", line 883, in _resolve_lookup
    current = current[bit]
              ~~~~~~~^^^^^
KeyError: 'lineaAuto'

During handling of the above exception, another exception occurred:

Traceback (most recent call last):
  File "/Users/andresrdrgz_/Documents/PACIFICO/venv/lib/python3.11/site-packages/django/template/base.py", line 893, in _resolve_lookup
    current = getattr(current, bit)
              ^^^^^^^^^^^^^^^^^^^^^
AttributeError: 'dict' object has no attribute 'lineaAuto'

During handling of the above exception, another exception occurred:

Traceback (most recent call last):
  File "/Users/andresrdrgz_/Documents/PACIFICO/venv/lib/python3.11/site-packages/django/template/base.py", line 899, in _resolve_lookup
    current = current[int(bit)]
                      ^^^^^^^^
ValueError: invalid literal for int() with base 10: 'lineaAuto'

During handling of the above exception, another exception occurred:

Traceback (most recent call last):
  File "/Users/andresrdrgz_/Documents/PACIFICO/venv/lib/python3.11/site-packages/django/template/base.py", line 906, in _resolve_lookup
    raise VariableDoesNotExist(
django.template.base.VariableDoesNotExist: Failed lookup for key [lineaAuto] in {'auxMonto2': Decimal('34925.43'), 'numero_cotizacion': 68, 'r1': Decimal('13.00'), 'tasaEstimada': Decimal('9.50'), 'calcComiCierreFinal': Decimal('13.84'), 'auxPlazoPago': 96, 'wrkLetraSinSeguros': Decimal('541.60'), 'wrkLetraSeguro': Decimal('27.50'), 'wrkMontoLetra': Decimal('569.10'), 'montoMensualSeguro': Decimal('0.00'), 'wrkLetraConSeguros': Decimal('569.10'), 'tablaTotalPagos': Decimal('54633.60'), 'nombreCliente': 'hasd', 'valorAuto': Decimal('35400.00'), 'abono': Decimal('5310.00'), 'salarioBaseMensual': Decimal('0.00'), 'totalDescuentosLegales': Decimal('0.00'), 'totalDescuentoDirecto': Decimal('0.00'), 'totalPagoVoluntario': Decimal('0.00'), 'salarioNetoActual': Decimal('0.00'), 'salarioNeto': Decimal('-569.10'), 'porSalarioNeto': Decimal('0.00'), 'totalIngresosAdicionales': Decimal('0.00'), 'totalIngresosMensualesCompleto': Decimal('0.00'), 'totalDescuentosLegalesCompleto': Decimal('0.00'), 'salarioNetoActualCompleto': Decimal('0.00'), 'salarioNetoCompleto': Decimal('-569.10'), 'porSalarioNetoCompleto': Decimal('0.00'), 'cosalarioBaseMensual': None, 'cototalDescuentosLegales': None, 'cototalDescuentoDirecto': None, 'cototalPagoVoluntario': None, 'cosalarioNetoActual': None, 'cosalarioNeto': None, 'coporSalarioNeto': None, 'cototalIngresosAdicionales': Decimal('0.00'), 'cototalIngresosMensualesCompleto': None, 'cototalDescuentosLegalesCompleto': None, 'cosalarioNetoActualCompleto': None, 'cosalarioNetoCompleto': None, 'coporSalarioNetoCompleto': None, 'porcentajeLetraSeguro': 0, 'coporcentajeLetraSeguro': 0, 'porcentajeLetraSeguroCompleto': 0, 'coporcentajeLetraSeguroCompleto': 0, 'familiarSalarioBaseMensual': 0, 'familiarSalarioNeto': Decimal('-569.10'), 'familiarporNetoActual': 0, 'familiarpoSalarioNeto': 0, 'familiarNetoActualCompleto': 0, 'familiarporNetoActualCompleto': 0, 'familiarSalarioNetoCompleto': Decimal('-569.10'), 'familiarporSalarioNeto': 0}
INFO:django.server:"POST /cotizacion/68/ HTTP/1.1" 200 209169
DEBUG:django.utils.autoreload:File /Users/andresrdrgz_/Documents/PACIFICO/venv/lib/python3.11/site-packages/django/contrib/messages/storage/session.py first seen with mtime 1732569332.5019946
DEBUG:django.utils.autoreload:File /Users/andresrdrgz_/Documents/PACIFICO/venv/lib/python3.11/site-packages/django/contrib/sessions/serializers.py first seen with mtime 1732569332.5685349
DEBUG:django.utils.autoreload:File /Users/andresrdrgz_/Documents/PACIFICO/venv/lib/python3.11/site-packages/django/contrib/messages/storage/cookie.py first seen with mtime 1732569332.5017526
DEBUG:django.utils.autoreload:File /Users/andresrdrgz_/anaconda3/lib/python3.11/_strptime.py first seen with mtime 1681948558.9095042
DEBUG:django.utils.autoreload:File /Users/andresrdrgz_/Documents/PACIFICO/venv/lib/python3.11/site-packages/django/contrib/messages/storage/fallback.py first seen with mtime 1732569332.5018916
DEBUG:django.utils.autoreload:File /Users/andresrdrgz_/Documents/PACIFICO/venv/lib/python3.11/site-packages/django/conf/locale/en/formats.py first seen with mtime 1732569332.0692546
DEBUG:django.utils.autoreload:File /Users/andresrdrgz_/Documents/PACIFICO/venv/lib/python3.11/site-packages/django/conf/locale/en/__init__.py first seen with mtime 1732569332.0690286
DEBUG:django.utils.autoreload:File /Users/andresrdrgz_/Documents/PACIFICO/venv/lib/python3.11/site-packages/django/contrib/messages/context_processors.py first seen with mtime 1732569332.500866
DEBUG:django.utils.autoreload:File /Users/andresrdrgz_/Documents/PACIFICO/venv/lib/python3.11/site-packages/django/template/context_processors.py first seen with mtime 1732569332.7133355
DEBUG:django.utils.autoreload:File /Users/andresrdrgz_/Documents/PACIFICO/venv/lib/python3.11/site-packages/django/contrib/auth/context_processors.py first seen with mtime 1732569332.2745264
DEBUG:django.utils.autoreload:File /Users/andresrdrgz_/Documents/PACIFICO/financiera/pacifico/viewsFideicomiso/cotizadorFideicomiso.py previous mtime: 1738609154.982212, current mtime: 1738609191.5386171
DEBUG:django.utils.autoreload:/Users/andresrdrgz_/Documents/PACIFICO/financiera/pacifico/viewsFideicomiso/cotizadorFideicomiso.py notified as changed. Signal results: [(<function template_changed at 0x105bacf40>, None), (<function translation_file_changed at 0x10666dc60>, None)].
INFO:django.utils.autoreload:/Users/andresrdrgz_/Documents/PACIFICO/financiera/pacifico/viewsFideicomiso/cotizadorFideicomiso.py changed, reloading.
