ERROR:root:'<=' not supported between instances of 'int' and 'NoneType'
DEBUG:django.db.backends:(0.000) SELECT "pacifico_aseguradora"."id", "pacifico_aseguradora"."descripcion", "pacifico_aseguradora"."codigo" FROM "pacifico_aseguradora"; args=(); alias=default
DEBUG:django.template:Exception while resolving variable 'lineaAuto' in template 'fideicomiso_form.html'.
Traceback (most recent call last):
  File "/Users/andresrdrgz_/Documents/PACIFICO/venv/lib/python3.11/site-packages/django/template/base.py", line 883, in _resolve_lookup
    current = current[bit]
              ~~~~~~~^^^^^
KeyError: 'lineaAuto'

During handling of the above exception, another exception occurred:

Traceback (most recent call last):
  File "/Users/andresrdrgz_/Documents/PACIFICO/venv/lib/python3.11/site-packages/django/template/base.py", line 893, in _resolve_lookup
    current = getattr(current, bit)
              ^^^^^^^^^^^^^^^^^^^^^
AttributeError: 'dict' object has no attribute 'lineaAuto'

During handling of the above exception, another exception occurred:

Traceback (most recent call last):
  File "/Users/andresrdrgz_/Documents/PACIFICO/venv/lib/python3.11/site-packages/django/template/base.py", line 899, in _resolve_lookup
    current = current[int(bit)]
                      ^^^^^^^^
ValueError: invalid literal for int() with base 10: 'lineaAuto'

During handling of the above exception, another exception occurred:

Traceback (most recent call last):
  File "/Users/andresrdrgz_/Documents/PACIFICO/venv/lib/python3.11/site-packages/django/template/base.py", line 906, in _resolve_lookup
    raise VariableDoesNotExist(
django.template.base.VariableDoesNotExist: Failed lookup for key [lineaAuto] in {'auxMonto2': Decimal('144011.23'), 'numero_cotizacion': 26, 'r1': Decimal('14.00'), 'tasaEstimada': Decimal('9.86'), 'calcComiCierreFinal': Decimal('13.20'), 'auxPlazoPago': 92, 'wrkLetraSinSeguros': Decimal('2323.45'), 'wrkLetraSeguro': Decimal('113.41'), 'wrkMontoLetra': Decimal('2436.86'), 'montoMensualSeguro': Decimal('0.00'), 'wrkLetraConSeguros': Decimal('2436.86'), 'tablaTotalPagos': Decimal('224191.12'), 'nombreCliente': 'BANCARIOS', 'valorAuto': Decimal('125000.00'), 'abono': Decimal('0.00'), 'salarioBaseMensual': Decimal('0.00'), 'totalDescuentosLegales': Decimal('0.00'), 'totalDescuentoDirecto': Decimal('0.00'), 'totalPagoVoluntario': Decimal('0.00'), 'salarioNetoActual': Decimal('0.00'), 'salarioNeto': Decimal('-2436.86'), 'porSalarioNeto': Decimal('0.00'), 'totalIngresosAdicionales': Decimal('0.00'), 'totalIngresosMensualesCompleto': Decimal('0.00'), 'totalDescuentosLegalesCompleto': Decimal('0.00'), 'salarioNetoActualCompleto': Decimal('0.00'), 'salarioNetoCompleto': Decimal('-2436.86'), 'porSalarioNetoCompleto': Decimal('0.00'), 'cosalarioBaseMensual': None, 'cototalDescuentosLegales': None, 'cototalDescuentoDirecto': None, 'cototalPagoVoluntario': None, 'cosalarioNetoActual': None, 'cosalarioNeto': None, 'coporSalarioNeto': None, 'cototalIngresosAdicionales': Decimal('0.00'), 'cototalIngresosMensualesCompleto': None, 'cototalDescuentosLegalesCompleto': None, 'cosalarioNetoActualCompleto': None, 'cosalarioNetoCompleto': None, 'coporSalarioNetoCompleto': None}
DEBUG:django.template:Exception while resolving variable 'lineaAuto' in template 'fideicomiso_form.html'.
Traceback (most recent call last):
  File "/Users/andresrdrgz_/Documents/PACIFICO/venv/lib/python3.11/site-packages/django/template/base.py", line 883, in _resolve_lookup
    current = current[bit]
              ~~~~~~~^^^^^
KeyError: 'lineaAuto'

During handling of the above exception, another exception occurred:

Traceback (most recent call last):
  File "/Users/andresrdrgz_/Documents/PACIFICO/venv/lib/python3.11/site-packages/django/template/base.py", line 893, in _resolve_lookup
    current = getattr(current, bit)
              ^^^^^^^^^^^^^^^^^^^^^
AttributeError: 'dict' object has no attribute 'lineaAuto'

During handling of the above exception, another exception occurred:

Traceback (most recent call last):
  File "/Users/andresrdrgz_/Documents/PACIFICO/venv/lib/python3.11/site-packages/django/template/base.py", line 899, in _resolve_lookup
    current = current[int(bit)]
                      ^^^^^^^^
ValueError: invalid literal for int() with base 10: 'lineaAuto'

During handling of the above exception, another exception occurred:

Traceback (most recent call last):
  File "/Users/andresrdrgz_/Documents/PACIFICO/venv/lib/python3.11/site-packages/django/template/base.py", line 906, in _resolve_lookup
    raise VariableDoesNotExist(
django.template.base.VariableDoesNotExist: Failed lookup for key [lineaAuto] in {'auxMonto2': Decimal('144011.23'), 'numero_cotizacion': 26, 'r1': Decimal('14.00'), 'tasaEstimada': Decimal('9.86'), 'calcComiCierreFinal': Decimal('13.20'), 'auxPlazoPago': 92, 'wrkLetraSinSeguros': Decimal('2323.45'), 'wrkLetraSeguro': Decimal('113.41'), 'wrkMontoLetra': Decimal('2436.86'), 'montoMensualSeguro': Decimal('0.00'), 'wrkLetraConSeguros': Decimal('2436.86'), 'tablaTotalPagos': Decimal('224191.12'), 'nombreCliente': 'BANCARIOS', 'valorAuto': Decimal('125000.00'), 'abono': Decimal('0.00'), 'salarioBaseMensual': Decimal('0.00'), 'totalDescuentosLegales': Decimal('0.00'), 'totalDescuentoDirecto': Decimal('0.00'), 'totalPagoVoluntario': Decimal('0.00'), 'salarioNetoActual': Decimal('0.00'), 'salarioNeto': Decimal('-2436.86'), 'porSalarioNeto': Decimal('0.00'), 'totalIngresosAdicionales': Decimal('0.00'), 'totalIngresosMensualesCompleto': Decimal('0.00'), 'totalDescuentosLegalesCompleto': Decimal('0.00'), 'salarioNetoActualCompleto': Decimal('0.00'), 'salarioNetoCompleto': Decimal('-2436.86'), 'porSalarioNetoCompleto': Decimal('0.00'), 'cosalarioBaseMensual': None, 'cototalDescuentosLegales': None, 'cototalDescuentoDirecto': None, 'cototalPagoVoluntario': None, 'cosalarioNetoActual': None, 'cosalarioNeto': None, 'coporSalarioNeto': None, 'cototalIngresosAdicionales': Decimal('0.00'), 'cototalIngresosMensualesCompleto': None, 'cototalDescuentosLegalesCompleto': None, 'cosalarioNetoActualCompleto': None, 'cosalarioNetoCompleto': None, 'coporSalarioNetoCompleto': None}
INFO:django.server:"POST /cotizacion/26/ HTTP/1.1" 200 199736
DEBUG:django.utils.autoreload:File /Users/andresrdrgz_/anaconda3/lib/python3.11/_strptime.py first seen with mtime 1681948558.9095042
DEBUG:django.utils.autoreload:File /Users/andresrdrgz_/Documents/PACIFICO/financiera/pacifico/viewsFideicomiso/cotizadorFideicomiso.py previous mtime: 1735407503.0977821, current mtime: 1736779276.6645827
DEBUG:django.utils.autoreload:/Users/andresrdrgz_/Documents/PACIFICO/financiera/pacifico/viewsFideicomiso/cotizadorFideicomiso.py notified as changed. Signal results: [(<function template_changed at 0x1065acf40>, None), (<function translation_file_changed at 0x10716dc60>, None)].
INFO:django.utils.autoreload:/Users/andresrdrgz_/Documents/PACIFICO/financiera/pacifico/viewsFideicomiso/cotizadorFideicomiso.py changed, reloading.
