ERROR:root:unsupported operand type(s) for *: 'decimal.Decimal' and 'float'
DEBUG:django.db.backends:(0.000) SELECT "pacifico_aseguradora"."id", "pacifico_aseguradora"."descripcion", "pacifico_aseguradora"."codigo" FROM "pacifico_aseguradora"; args=(); alias=default
DEBUG:django.template:Exception while resolving variable 'lineaAuto' in template 'fideicomiso_form.html'.
Traceback (most recent call last):
  File "/Users/andresrdrgz_/Documents/PACIFICO/venv/lib/python3.11/site-packages/django/template/base.py", line 883, in _resolve_lookup
    current = current[bit]
              ~~~~~~~^^^^^
KeyError: 'lineaAuto'

During handling of the above exception, another exception occurred:

Traceback (most recent call last):
  File "/Users/andresrdrgz_/Documents/PACIFICO/venv/lib/python3.11/site-packages/django/template/base.py", line 893, in _resolve_lookup
    current = getattr(current, bit)
              ^^^^^^^^^^^^^^^^^^^^^
AttributeError: 'dict' object has no attribute 'lineaAuto'

During handling of the above exception, another exception occurred:

Traceback (most recent call last):
  File "/Users/andresrdrgz_/Documents/PACIFICO/venv/lib/python3.11/site-packages/django/template/base.py", line 899, in _resolve_lookup
    current = current[int(bit)]
                      ^^^^^^^^
ValueError: invalid literal for int() with base 10: 'lineaAuto'

During handling of the above exception, another exception occurred:

Traceback (most recent call last):
  File "/Users/andresrdrgz_/Documents/PACIFICO/venv/lib/python3.11/site-packages/django/template/base.py", line 906, in _resolve_lookup
    raise VariableDoesNotExist(
django.template.base.VariableDoesNotExist: Failed lookup for key [lineaAuto] in {'auxMonto2': Decimal('14542.91'), 'r1': Decimal('14.00'), 'tasaEstimada': Decimal('9.10'), 'calcComiCierreFinal': Decimal('15.06'), 'auxPlazoPago': 72, 'wrkLetraSinSeguros': Decimal('271.29'), 'wrkLetraSeguro': Decimal('11.45'), 'wrkMontoLetra': Decimal('282.74'), 'montoMensualSeguro': Decimal('0.00'), 'wrkLetraConSeguros': Decimal('282.74'), 'tablaTotalPagos': Decimal('20357.28'), 'nombreCliente': 'asd', 'valorAuto': Decimal('12351.00'), 'abono': Decimal('0.00'), 'salarioBaseMensual': Decimal('1500.00'), 'totalDescuentosLegales': Decimal('263.08'), 'totalDescuentoDirecto': Decimal('350.00'), 'totalPagoVoluntario': Decimal('120.00'), 'salarioNetoActual': Decimal('766.92'), 'salarioNeto': Decimal('484.18'), 'porSalarioNeto': Decimal('32.28'), 'totalIngresosAdicionales': Decimal('0.00'), 'totalIngresosMensualesCompleto': Decimal('1500.00'), 'totalDescuentosLegalesCompleto': Decimal('263.08'), 'salarioNetoActualCompleto': Decimal('766.92'), 'salarioNetoCompleto': Decimal('484.18'), 'porSalarioNetoCompleto': Decimal('32.28'), 'numero_cotizacion': 19}
DEBUG:django.template:Exception while resolving variable 'lineaAuto' in template 'fideicomiso_form.html'.
Traceback (most recent call last):
  File "/Users/andresrdrgz_/Documents/PACIFICO/venv/lib/python3.11/site-packages/django/template/base.py", line 883, in _resolve_lookup
    current = current[bit]
              ~~~~~~~^^^^^
KeyError: 'lineaAuto'

During handling of the above exception, another exception occurred:

Traceback (most recent call last):
  File "/Users/andresrdrgz_/Documents/PACIFICO/venv/lib/python3.11/site-packages/django/template/base.py", line 893, in _resolve_lookup
    current = getattr(current, bit)
              ^^^^^^^^^^^^^^^^^^^^^
AttributeError: 'dict' object has no attribute 'lineaAuto'

During handling of the above exception, another exception occurred:

Traceback (most recent call last):
  File "/Users/andresrdrgz_/Documents/PACIFICO/venv/lib/python3.11/site-packages/django/template/base.py", line 899, in _resolve_lookup
    current = current[int(bit)]
                      ^^^^^^^^
ValueError: invalid literal for int() with base 10: 'lineaAuto'

During handling of the above exception, another exception occurred:

Traceback (most recent call last):
  File "/Users/andresrdrgz_/Documents/PACIFICO/venv/lib/python3.11/site-packages/django/template/base.py", line 906, in _resolve_lookup
    raise VariableDoesNotExist(
django.template.base.VariableDoesNotExist: Failed lookup for key [lineaAuto] in {'auxMonto2': Decimal('14542.91'), 'r1': Decimal('14.00'), 'tasaEstimada': Decimal('9.10'), 'calcComiCierreFinal': Decimal('15.06'), 'auxPlazoPago': 72, 'wrkLetraSinSeguros': Decimal('271.29'), 'wrkLetraSeguro': Decimal('11.45'), 'wrkMontoLetra': Decimal('282.74'), 'montoMensualSeguro': Decimal('0.00'), 'wrkLetraConSeguros': Decimal('282.74'), 'tablaTotalPagos': Decimal('20357.28'), 'nombreCliente': 'asd', 'valorAuto': Decimal('12351.00'), 'abono': Decimal('0.00'), 'salarioBaseMensual': Decimal('1500.00'), 'totalDescuentosLegales': Decimal('263.08'), 'totalDescuentoDirecto': Decimal('350.00'), 'totalPagoVoluntario': Decimal('120.00'), 'salarioNetoActual': Decimal('766.92'), 'salarioNeto': Decimal('484.18'), 'porSalarioNeto': Decimal('32.28'), 'totalIngresosAdicionales': Decimal('0.00'), 'totalIngresosMensualesCompleto': Decimal('1500.00'), 'totalDescuentosLegalesCompleto': Decimal('263.08'), 'salarioNetoActualCompleto': Decimal('766.92'), 'salarioNetoCompleto': Decimal('484.18'), 'porSalarioNetoCompleto': Decimal('32.28'), 'numero_cotizacion': 19}
INFO:django.server:"POST /cotizacion/19/ HTTP/1.1" 200 187491
DEBUG:django.utils.autoreload:File /Users/andresrdrgz_/anaconda3/lib/python3.11/_strptime.py first seen with mtime 1681948558.9095042
DEBUG:django.utils.autoreload:File /Users/andresrdrgz_/Documents/PACIFICO/financiera/pacifico/views.py previous mtime: 1736372382.2801082, current mtime: 1736372425.442165
DEBUG:django.utils.autoreload:/Users/andresrdrgz_/Documents/PACIFICO/financiera/pacifico/views.py notified as changed. Signal results: [(<function template_changed at 0x105eacf40>, None), (<function translation_file_changed at 0x107b6dbc0>, None)].
INFO:django.utils.autoreload:/Users/andresrdrgz_/Documents/PACIFICO/financiera/pacifico/views.py changed, reloading.
